<?xml version="1.0" encoding="utf-8"?>
<!-- This URDF was automatically created by SolidWorks to URDF Exporter! Originally created by Stephen Brawner (brawner@gmail.com) 
     Commit Version: 1.6.0-4-g7f85cfe  Build Version: 1.6.7995.38578
     For more information, please see http://wiki.ros.org/sw_urdf_exporter -->
<robot name="arm_only_gripper" xmlns:xacro="http://www.ros.org/wiki/xacro">
  <xacro:arg name="use_embedded_ros2_control" default="true"/>
  <link
    name="ARM_BASE_LINK">
    <inertial>
      <origin
        xyz="0 0 0"
        rpy="0 0 0" />
      <mass
        value="0.19" />
      <inertia
        ixx="0"
        ixy="0"
        ixz="0"
        iyy="0"
        iyz="0"
        izz="0" />
    </inertial>
    <visual>
      <origin
        xyz="0 0 0"
        rpy="0 0 0" />
      <geometry>
        <mesh
          filename="file://$(find arm_only_description)/meshes/ARM_BASE_LINK.STL" />
      </geometry>
      <material
        name="">
        <color
          rgba="0.89804 0.91765 0.92941 1" />
      </material>
    </visual>
  

    <collision name="ARM_BASE_LINK_120x120x15p7_box">
      <origin xyz="0 0 0.00785" rpy="0 0 0" />
      <geometry>
        <box size="0.12 0.12 0.0137" />
      </geometry>
    </collision>
  </link>
  <joint
    name="JOINT1"
    type="revolute">
    <origin
      xyz="0 0 0.016"
      rpy="0 0 0" />
    <parent
      link="ARM_BASE_LINK" />
    <child
      link="LINK1" />
    <axis
      xyz="0 0 1" />
    <limit
      lower="-5.759587" upper="5.759587" effort="35" velocity="1.2" />
      <dynamics damping="2" friction="0.3" />
  </joint>
  <link
    name="LINK1">
    <inertial>
      <origin
        xyz="0 0 0.01"
        rpy="0 0 0" />
      <mass
        value="1.37" />
      <inertia
        ixx="0"
        ixy="0"
        ixz="0"
        iyy="0"
        iyz="0"
        izz="0" />
    </inertial>
    <visual>
      <origin
        xyz="0 0 0"
        rpy="0 0 0" />
      <geometry>
        <mesh
          filename="file://$(find arm_only_description)/meshes/LINK1.STL" />
      </geometry>
      <material
        name="">
        <color
          rgba="0.89804 0.91765 0.92941 1" />
      </material>
    </visual>
  

    <collision name="LINK1_digeut_bottom_box">
      <origin xyz="0 0 0.00823" rpy="0 0 1.5708" />
      <geometry>
        <box size="0.141 0.0855 0.0175" />
      </geometry>
    </collision>

    <collision name="LINK1_digeut_right_box">
      <origin xyz="0 0.06525 0.064105" rpy="0 0 1.5708" />
      <geometry>
        <box size="0.013 0.087 0.09675" />
      </geometry>
    </collision>

    <collision name="LINK1_digeut_left_box">
      <origin xyz="0 -0.06525 0.064105" rpy="0 0 1.5708" />
      <geometry>
        <box size="0.013 0.087 0.09675" />
      </geometry>
    </collision>
  </link>
  <link
    name="LINK2">
    <inertial>
      <origin
        xyz="-0.05 0 0"
        rpy="0 0 0" />
      <mass
        value="1.53" />
      <inertia
        ixx="0"
        ixy="0"
        ixz="0"
        iyy="0.02"
        iyz="0"
        izz="0.02" />
    </inertial>
    <visual>
      <origin
        xyz="0 0 0"
        rpy="0 0 0" />
      <geometry>
        <mesh
          filename="file://$(find arm_only_description)/meshes/LINK2.STL" />
      </geometry>
      <material
        name="">
        <color
          rgba="0.89804 0.91765 0.92941 1" />
      </material>
    </visual>
  

    <collision name="LINK2_manual_cyl_01_y_axis">
      <origin xyz="0 0 0" rpy="1.5708 0 0" />
      <geometry>
        <cylinder radius="0.043" length="0.1105" />
      </geometry>
    </collision>

    <collision name="LINK2_manual_cyl_02_x_axis">
      <origin xyz="-0.155525 0 0" rpy="0 1.5708 0" />
      <geometry>
        <cylinder radius="0.022" length="0.31105" />
      </geometry>
    </collision>

    <collision name="LINK2_manual_cyl_03_y_axis">
      <origin xyz="-0.35042 0 -0.00031" rpy="1.5708 0 0" />
      <geometry>
        <cylinder radius="0.042" length="0.061" />
      </geometry>
    </collision>
  </link>
  <joint
    name="JOINT2"
    type="revolute">
    <origin
      xyz="0 0 0.07"
      rpy="0 0 0" />
    <parent
      link="LINK1" />
    <child
      link="LINK2" />
    <axis xyz="0 -1 0" />
    <limit lower="-0.5" upper="0.10472" effort="35" velocity="1.2" />
      <dynamics damping="2" friction="0.3" />
  </joint>
  <link
    name="LINK3">
    <inertial>
      <origin
        xyz="0.05 0 0.04"
        rpy="0 0 0" />
      <mass
        value="1.07" />
      <inertia
        ixx="0"
        ixy="0"
        ixz="0"
        iyy="0.01"
        iyz="0"
        izz="0.01" />
    </inertial>
    <visual>
      <origin
        xyz="0 0 0"
        rpy="0 0 0" />
      <geometry>
        <mesh
          filename="file://$(find arm_only_description)/meshes/LINK3.STL" />
      </geometry>
      <material
        name="">
        <color
          rgba="0.29804 0.29804 0.29804 1" />
      </material>
    </visual>
  

    <collision name="LINK3_manual_cyl_01_x_axis">
      <origin xyz="0.151715 0 0.08328" rpy="0 1.5708 0" />
      <geometry>
        <cylinder radius="0.022" length="0.15233" />
      </geometry>
    </collision>

    <collision name="LINK3_manual_cyl_02_x_axis">
      <origin xyz="0.26088 0 0.08328" rpy="0 1.5708 0" />
      <geometry>
        <cylinder radius="0.0365" length="0.068" />
      </geometry>
    </collision>

    <collision name="LINK3_joint3_side_box_minus_y">
      <origin xyz="0.005 -0.03635 0.022" rpy="0 0 0" />
      <geometry>
        <box size="0.070 0.0085 0.105" />
      </geometry>
    </collision>

    <collision name="LINK3_joint3_side_box_plus_y">
      <origin xyz="0.005 0.03835 0.022" rpy="0 0 0" />
      <geometry>
        <box size="0.070 0.0085 0.105" />
      </geometry>
    </collision>

    <collision name="LINK3_joint3_slant_cyl_30deg">
      <origin xyz="0.0175 -0.00025 0.062" rpy="0 1.0472 0" />
      <geometry>
        <cylinder radius="0.029" length="0.076" />
      </geometry>
    </collision>

    <collision name="LINK3_joint3_slant_cyl_5deg">
      <origin xyz="0.075 -0.00025 0.082" rpy="0 1.4835 0" />
      <geometry>
        <cylinder radius="0.0275" length="0.080" />
      </geometry>
    </collision>
  </link>
  <joint
    name="JOINT3"
    type="revolute">
    <origin
      xyz="-0.35 -0.00025005 0"
      rpy="0 0 0" />
    <parent
      link="LINK2" />
    <child
      link="LINK3" />
    <axis xyz="0 1 0" />
    <limit lower="-3.228859" upper="-0.087266" effort="35" velocity="1.2" />
      <dynamics damping="2" friction="0.3" />
  </joint>
  <link
    name="LINK4">
    <inertial>
      <origin
        xyz="0.01 0 0"
        rpy="0 0 0" />
      <mass
        value="0.2" />
      <inertia
        ixx="0"
        ixy="0"
        ixz="0"
        iyy="0"
        iyz="0"
        izz="0" />
    </inertial>
    <visual>
      <origin
        xyz="0 0 0"
        rpy="1.5708 0 0" />
      <geometry>
        <mesh
          filename="file://$(find arm_only_description)/meshes/LINK4.STL" />
      </geometry>
      <material
        name="">
        <color
          rgba="0.20392 0.20392 0.20392 1" />
      </material>
    </visual>
  

    <collision name="LINK4_manual_box_01_center">
      <origin xyz="0.0063 0 0" rpy="0 0 0" />
      <geometry>
        <box size="0.008 0.071 0.058" />
      </geometry>
    </collision>

    <collision name="LINK4_manual_box_02_plus_y">
      <origin xyz="0.0345 0.0385 0" rpy="0 0 0" />
      <geometry>
        <box size="0.064 0.008 0.057" />
      </geometry>
    </collision>

    <collision name="LINK4_manual_box_03_minus_y">
      <origin xyz="0.0345 -0.0385 0" rpy="0 0 0" />
      <geometry>
        <box size="0.064 0.008 0.057" />
      </geometry>
    </collision>
  </link>
  <joint
    name="JOINT4"
    type="revolute">
    <origin
      xyz="0.29265 0 0.083467"
      rpy="0 0 0" />
    <parent
      link="LINK3" />
    <child
      link="LINK4" />
    <axis
      xyz="1 0 0" />
    <limit
      lower="-1.919862" upper="1.919862" effort="35" velocity="1.2" />
      <dynamics damping="2" friction="0.3" />
  </joint>
  <link
    name="LINK5">
    <inertial>
      <origin
        xyz="0.02 0 0"
        rpy="0 0 0" />
      <mass
        value="0.49" />
      <inertia
        ixx="0"
        ixy="0"
        ixz="0"
        iyy="0"
        iyz="0"
        izz="0" />
    </inertial>
    <visual>
      <origin
        xyz="0 0 0"
        rpy="1.5708 0 0" />
      <geometry>
        <mesh
          filename="file://$(find arm_only_description)/meshes/LINK5.STL" />
      </geometry>
      <material
        name="">
        <color
          rgba="0.20392 0.20392 0.20392 1" />
      </material>
    </visual>
  

    <collision name="LINK5_manual_cyl_01_y_axis">
      <origin xyz="0 0 0" rpy="1.5708 0 0" />
      <geometry>
        <cylinder radius="0.028" length="0.0585" />
      </geometry>
    </collision>

    <collision name="LINK5_manual_box_02_center_x">
      <origin xyz="0.032 0 0" rpy="0 0 0" />
      <geometry>
        <box size="0.0105 0.0585 0.0565" />
      </geometry>
    </collision>

    <collision name="LINK5_manual_box_03_minus_y">
      <origin xyz="0.0045 -0.0315 0" rpy="0 0 0" />
      <geometry>
        <box size="0.0655 0.0055 0.0565" />
      </geometry>
    </collision>

    <collision name="LINK5_manual_box_04_plus_y">
      <origin xyz="0.0045 0.0315 0" rpy="0 0 0" />
      <geometry>
        <box size="0.0655 0.0065 0.0565" />
      </geometry>
    </collision>
  </link>
  <joint
    name="JOINT5"
    type="revolute">
    <origin
      xyz="0.038 0 0"
      rpy="0 0 0" />
    <parent
      link="LINK4" />
    <child
      link="LINK5" />
    <axis
      xyz="0 0 1" />
    <limit
      lower="-1.570796" upper="1.570796" effort="35" velocity="1.2" />
      <dynamics damping="2" friction="0.3" />
  </joint>
  <link
    name="LINK6">
    <inertial>
      <origin
        xyz="0.01 0 0"
        rpy="0 0 0" />
      <mass
        value="0.36" />
      <inertia
        ixx="0"
        ixy="0"
        ixz="0"
        iyy="0"
        iyz="0"
        izz="0" />
    </inertial>
    <visual>
      <origin
        xyz="0 0 0"
        rpy="0 0 0" />
      <geometry>
        <mesh
          filename="file://$(find arm_only_description)/meshes/LINK6.STL" />
      </geometry>
      <material
        name="">
        <color
          rgba="1 0.6 0 1" />
      </material>
    </visual>
  

    <collision name="LINK6_manual_cyl_01_x_axis">
      <origin xyz="-0.02175 0 0" rpy="0 1.5708 0" />
      <geometry>
        <cylinder radius="0.0275" length="0.044" />
      </geometry>
    </collision>

    <collision name="LINK6_manual_cyl_02_x_axis">
      <origin xyz="0.025 0 0" rpy="0 1.5708 0" />
      <geometry>
        <cylinder radius="0.0315" length="0.0505" />
      </geometry>
    </collision>
  </link>
  <joint
    name="JOINT6"
    type="revolute">
    <origin
      xyz="0.08175 0 0"
      rpy="0 0 0" />
    <parent
      link="LINK5" />
    <child
      link="LINK6" />
    <axis
      xyz="-1 0 0" />
    <limit
      lower="0.523599" upper="5.759587" effort="35" velocity="1.2" />
      <dynamics damping="2" friction="0.3" />
  </joint>
  <link
    name="gripper_base">
    <inertial>
      <origin xyz="0 0 0" rpy="0 0 0" />
      <mass value="0.8" />
      <inertia ixx="0.0010" ixy="0" ixz="0" iyy="0.0010" iyz="0" izz="0.0010" />
    </inertial>
    <visual>
      <origin
        xyz="0 0 0"
        rpy="0 0 0" />
      <geometry>
        <mesh
          filename="file://$(find arm_only_description)/meshes/gripper_base.STL" />
      </geometry>
      <material
        name="">
        <color
          rgba="1 0.6 0 1" />
      </material>
    </visual>

    <!-- GRIPPER_COLLISION_TUNING_START: gripper_base -->
    <!-- GRIPPER_COLLISION_TUNING_END: gripper_base -->
  
    <collision name="gripper_base_sw_box_01_main_swapped">
      <origin xyz="0.02107 0 0" rpy="0 0 0" />
      <geometry>
        <box size="0.0295 0.2015 0.0515" />
      </geometry>
    </collision>
  </link>
  <joint
    name="gripper_mount_joint"
    type="fixed">
    <origin
      xyz="0.04825 0 0"
      rpy="-0.16782 0 0" />
    <parent
      link="LINK6" />
    <child
      link="gripper_base" />
  </joint>
  <link
    name="drive_gear">
    <inertial>
      <origin xyz="0 0 0" rpy="0 0 0" />
      <mass value="0.05" />
      <inertia ixx="0.00001" ixy="0" ixz="0" iyy="0.00001" iyz="0" izz="0.00001" />
    </inertial>

    <visual name="drive_gear_clean_visual">
      <origin xyz="0 0 0" rpy="0 0 0" />
      <geometry>
        <mesh filename="file://$(find arm_only_description)/meshes/drive_gear_clean.STL" />
      </geometry>
      <material name="drive_gear_mat">
        <color rgba="0.35 0.35 0.35 1" />
      </material>
    </visual>

    <!-- GRIPPER_COLLISION_TUNING_START: drive_gear -->
    <!-- GRIPPER_COLLISION_TUNING_END: drive_gear -->
  </link>
  <joint
    name="JOINT7"
    type="revolute">
    <origin
      xyz="0.030611 9.6005E-05 1.6265E-05"
      rpy="0 0 0" />
    <parent
      link="gripper_base" />
    <child
      link="drive_gear" />
    <axis
      xyz="-1 0 0" />
    <limit
      lower="-1.70000" upper="45.00000" effort="50" velocity="8.0" />
      <dynamics damping="4.0" friction="1.0" />
  </joint>
  <link
    name="LEFT_PLATE">
    <inertial>
      <origin xyz="0 0 0" rpy="0 0 0" />
      <mass value="0.15" />
      <inertia ixx="0.00008" ixy="0" ixz="0" iyy="0.00008" iyz="0" izz="0.00008" />
    </inertial>

    <visual name="LEFT_PLATE_clean_visual">
      <origin xyz="0 0 0" rpy="0 0 0" />
      <geometry>
        <mesh filename="file://$(find arm_only_description)/meshes/LEFT_PLATE_clean.STL" />
      </geometry>
      <material name="LEFT_PLATE_mat">
        <color rgba="0.79216 0.81961 0.93333 1" />
      </material>
    </visual>

    <!-- GRIPPER_COLLISION_TUNING_START: LEFT_PLATE -->
    <!-- GRIPPER_COLLISION_TUNING_END: LEFT_PLATE -->
  
    <collision name="LEFT_PLATE_sw_box_01_main">
      <origin xyz="0.07 -0.016 0.021" rpy="0 0 0" />
      <geometry>
        <box size="0.111 0.013 0.082" />
      </geometry>
    </collision>
  </link>
  <joint
    name="LEFT_PLATE_JOINT"
    type="prismatic">
    <origin
      xyz="0.0211 0.1 -0.022"
      rpy="0 0 0" />
    <parent
      link="gripper_base" />
    <child
      link="LEFT_PLATE" />
    <axis xyz="-0 -1 -0" />
    <mimic joint="JOINT7" multiplier="0.0166667" offset="0.0" />
    <limit
      lower="0.0" upper="0.070" effort="80" velocity="1.0" />
    <dynamics damping="20.0" friction="8.0" />
  </joint>
  <link
    name="RIGHT_PLATE">
    <inertial>
      <origin xyz="0 0 0" rpy="0 0 0" />
      <mass value="0.15" />
      <inertia ixx="0.00008" ixy="0" ixz="0" iyy="0.00008" iyz="0" izz="0.00008" />
    </inertial>

    <visual name="RIGHT_PLATE_clean_visual">
      <origin xyz="0 0 0" rpy="0 0 0" />
      <geometry>
        <mesh filename="file://$(find arm_only_description)/meshes/RIGHT_PLATE.STL" />
      </geometry>
      <material name="RIGHT_PLATE_mat">
        <color rgba="0.79216 0.81961 0.93333 1" />
      </material>
    </visual>

    <!-- GRIPPER_COLLISION_TUNING_START: RIGHT_PLATE -->
    <!-- GRIPPER_COLLISION_TUNING_END: RIGHT_PLATE -->
  
    <collision name="RIGHT_PLATE_sw_box_01_main">
      <origin xyz="0.07 0.016 -0.023" rpy="0 0 0" />
      <geometry>
        <box size="0.111 0.013 0.082" />
      </geometry>
    </collision>
  </link>
  <joint
    name="RIGHT_PLATE_JOINT"
    type="prismatic">
    <origin
      xyz="0.0211 -0.1 0.022"
      rpy="0 0 0" />
    <parent
      link="gripper_base" />
    <child
      link="RIGHT_PLATE" />
    <axis
      xyz="0 1 0" />
    <mimic joint="JOINT7" multiplier="0.0166667" offset="0.0" />
    <limit
      lower="0.0" upper="0.070" effort="80" velocity="1.0" />
    <dynamics damping="20.0" friction="8.0" />
  </joint>


  <link name="gripper_tcp"/>

  <joint name="gripper_tcp_joint" type="fixed">
    <origin xyz="0.0904 9.6005E-05 -0.0001" rpy="0 0 0" />
    <parent link="gripper_base" />
    <child link="gripper_tcp" />
  </joint>



  <!-- ROS2_CONTROL_STANDARD_START -->
  <!-- EMBEDDED_ROS2_CONTROL_WRAP_START -->
  <xacro:if value="$(arg use_embedded_ros2_control)">
  <ros2_control name="GazeboSystem" type="system">
    <hardware>
      <plugin>gazebo_ros2_control/GazeboSystem</plugin>
    </hardware>

    <joint name="JOINT1">
      <command_interface name="position" />
      <state_interface name="position"><param name="initial_value">-0.0318</param></state_interface>
      <state_interface name="velocity" />
      <state_interface name="effort" />
    </joint>
    <joint name="JOINT2">
      <command_interface name="position" />
      <state_interface name="position"><param name="initial_value">-0.2002</param></state_interface>
      <state_interface name="velocity" />
      <state_interface name="effort" />
    </joint>
    <joint name="JOINT3">
      <command_interface name="position" />
      <state_interface name="position"><param name="initial_value">-0.2955</param></state_interface>
      <state_interface name="velocity" />
      <state_interface name="effort" />
    </joint>
    <joint name="JOINT4">
      <command_interface name="position" />
      <state_interface name="position"><param name="initial_value">0.0106</param></state_interface>
      <state_interface name="velocity" />
      <state_interface name="effort" />
    </joint>
    <joint name="JOINT5">
      <command_interface name="position" />
      <state_interface name="position"><param name="initial_value">0.0404</param></state_interface>
      <state_interface name="velocity" />
      <state_interface name="effort" />
    </joint>
    <joint name="JOINT6">
      <command_interface name="position" />
      <state_interface name="position"><param name="initial_value">3.3295</param></state_interface>
      <state_interface name="velocity" />
      <state_interface name="effort" />
    </joint>
    <joint name="JOINT7">
      <command_interface name="position" />
      <state_interface name="position"><param name="initial_value">0.0</param></state_interface>
      <state_interface name="velocity" />
      <state_interface name="effort" />
    </joint>
    <joint name="LEFT_PLATE_JOINT">
      <command_interface name="position" />
      <state_interface name="position"><param name="initial_value">0.0</param></state_interface>
      <state_interface name="velocity" />
      <state_interface name="effort" />
    </joint>
    <joint name="RIGHT_PLATE_JOINT">
      <command_interface name="position" />
      <state_interface name="position"><param name="initial_value">0.0</param></state_interface>
      <state_interface name="velocity" />
      <state_interface name="effort" />
    </joint>
  </ros2_control>
  </xacro:if>
  <!-- EMBEDDED_ROS2_CONTROL_WRAP_END -->
  <!-- EMBEDDED_GAZEBO_ROS2_CONTROL_PLUGIN_WRAP_START -->
  <xacro:if value="$(arg use_embedded_ros2_control)">
  </xacro:if>
  <!-- EMBEDDED_GAZEBO_ROS2_CONTROL_PLUGIN_WRAP_END -->
  <!-- ROS2_CONTROL_STANDARD_END -->


  <!-- Gripper pose-check stabilization: prevent passive gripper parts from sagging before controllers are added -->
  <gazebo reference="gripper_base">
    <gravity>false</gravity>
    <selfCollide>false</selfCollide>
  </gazebo>

  <gazebo reference="drive_gear">
    <gravity>false</gravity>
    <selfCollide>false</selfCollide>
  </gazebo>

  <gazebo reference="LEFT_PLATE">
    <gravity>false</gravity>
    <selfCollide>false</selfCollide>
  </gazebo>

  <gazebo reference="RIGHT_PLATE">
    <gravity>false</gravity>
    <selfCollide>false</selfCollide>
  </gazebo>
<!-- Gazebo: fix the actual root/base links so the robot body does not float or stand up. -->

  <gazebo>
    <plugin filename="libgazebo_ros2_control.so" name="gazebo_ros2_control">
      <robot_param>robot_description</robot_param>
      <robot_param_node>robot_state_publisher</robot_param_node>
      <parameters>$(find arm_only_moveit_config)/config/ros2_controllers.yaml</parameters>
      <hold_joints>true</hold_joints>
    </plugin>
  </gazebo>

</robot>